Workbook

Sheet Data
A1: InvoiceNumber | B1: Customer | C1: CustomerEmail | D1: InvoiceDate | E1: TermsDays | F1: DueDate | G1: Amount | H1: Status | I1: PaymentDate | J1: AmountPaid | K1: DaysToPay | L1: DaysLateAtPayment | M1: DaysPastDueNow | N1: Bucket | O1: OpenAmount | P1: OpenValueXAge
A2: INV-5001 | B2: Vantage Media Group | C2: ap@vantagemedia.group | D2: 45680 | E2: 30 | F2: 45710 | G2: 5050 | H2: Paid | I2: 45750 | J2: 5050 | K2: 70 | L2: 40 | M2: =IF($H2="Outstanding",MAX(0,Summary!$B$3-$F2),"") | N2: =IF($M2="","",IF($M2=0,"Current",IF($M2<=30,"1-30",IF($M2<=60,"31-60",IF($M2<=90,"61-90","90+"))))) | O2: =IF($H2="Outstanding",$G2,0) -> 0 | P2: =$O2*IF($M2="",0,$M2) -> 0
A3: INV-5002 | B3: Seoul Pharma Trading | C3: finance@seoulpharma.co | D3: 45660 | E3: 30 | F3: 45690 | G3: 8350 | H3: Paid | I3: 45716 | J3: 8350 | K3: 56 | L3: 26 | M3: =IF($H3="Outstanding",MAX(0,Summary!$B$3-$F3),"") | N3: =IF($M3="","",IF($M3=0,"Current",IF($M3<=30,"1-30",IF($M3<=60,"31-60",IF($M3<=90,"61-90","90+"))))) | O3: =IF($H3="Outstanding",$G3,0) -> 0 | P3: =$O3*IF($M3="",0,$M3) -> 0
A4: INV-5003 | B4: Northgate Property Mgmt | C4: vendors@northgatepm.com | D4: 45663 | E4: 30 | F4: 45693 | G4: 4100 | H4: Paid | I4: 45747 | J4: 4100 | K4: 84 | L4: 52 | M4: =IF($H4="Outstanding",MAX(0,Summary!$B$3-$F4),"") | N4: =IF($M4="","",IF($M4=0,"Current",IF($M4<=30,"1-30",IF($M4<=60,"31-60",IF($M4<=90,"61-90","90+"))))) | O4: =IF($H4="Outstanding",$G4,0) -> 0 | P4: =$O4*IF($M4="",0,$M4) -> 0
A5: INV-5004 | B5: Granite Civil Group | C5: ap@granitecivil.com | D5: 45673 | E5: 45 | F5: 45718 | G5: 34250 | H5: Paid | I5: 45755 | J5: 34250 | K5: 82 | L5: 37 | M5: =IF($H5="Outstanding",MAX(0,Summary!$B$3-$F5),"") | N5: =IF($M5="","",IF($M5=0,"Current",IF($M5<=30,"1-30",IF($M5<=60,"31-60",IF($M5<=90,"61-90","90+"))))) | O5: =IF($H5="Outstanding",$G5,0) -> 0 | P5: =$O5*IF($M5="",0,$M5) -> 0
A6: INV-5005 | B6: BlueRidge Hotels | C6: karen.wu@blueridgehotels.com | D6: 45667 | E6: 30 | F6: 45697 | G6: 14200 | H6: Paid | I6: 45709 | J6: 14200 | K6: 42 | L6: 12 | M6: =IF($H6="Outstanding",MAX(0,Summary!$B$3-$F6),"") | N6: =IF($M6="","",IF($M6=0,"Current",IF($M6<=30,"1-30",IF($M6<=60,"31-60",IF($M6<=90,"61-90","90+"))))) | O6: =IF($H6="Outstanding",$G6,0) -> 0 | P6: =$O6*IF($M6="",0,$M6) -> 0
A7: INV-5006 | B7: Stellar Staffing Co | C7: finance@stellarstaffing.co | D7: 45673 | E7: 15 | F7: 45688 | G7: 9150 | H7: Paid | I7: 45694 | J7: 9150 | K7: 21 | L7: 6 | M7: =IF($H7="Outstanding",MAX(0,Summary!$B$3-$F7),"") | N7: =IF($M7="","",IF($M7=0,"Current",IF($M7<=30,"1-30",IF($M7<=60,"31-60",IF($M7<=90,"61-90","90+"))))) | O7: =IF($H7="Outstanding",$G7,0) -> 0 | P7: =$O7*IF($M7="",0,$M7) -> 0
A8: INV-5007 | B8: BlueRidge Hotels | C8: karen.wu@blueridgehotels.com | D8: 45677 | E8: 30 | F8: 45707 | G8: 6900 | H8: Paid | I8: 45723 | J8: 6900 | K8: 46 | L8: 16 | M8: =IF($H8="Outstanding",MAX(0,Summary!$B$3-$F8),"") | N8: =IF($M8="","",IF($M8=0,"Current",IF($M8<=30,"1-30",IF($M8<=60,"31-60",IF($M8<=90,"61-90","90+"))))) | O8: =IF($H8="Outstanding",$G8,0) -> 0 | P8: =$O8*IF($M8="",0,$M8) -> 0
A9: INV-5008 | B9: Bluefin Seafood Dist | C9: payables@bluefindist.com | D9: 45681 | E9: 30 | F9: 45711 | G9: 8550 | H9: Paid | I9: 45737 | J9: 8550 | K9: 56 | L9: 26 | M9: =IF($H9="Outstanding",MAX(0,Summary!$B$3-$F9),"") | N9: =IF($M9="","",IF($M9=0,"Current",IF($M9<=30,"1-30",IF($M9<=60,"31-60",IF($M9<=90,"61-90","90+"))))) | O9: =IF($H9="Outstanding",$G9,0) -> 0 | P9: =$O9*IF($M9="",0,$M9) -> 0
A10: INV-5009 | B10: Ridgeline Builders | C10: ap@ridgelinebuilders.com | D10: 45660 | E10: 30 | F10: 45690 | G10: 10950 | H10: Paid | I10: 45726 | J10: 10950 | K10: 66 | L10: 36 | M10: =IF($H10="Outstanding",MAX(0,Summary!$B$3-$F10),"") | N10: =IF($M10="","",IF($M10=0,"Current",IF($M10<=30,"1-30",IF($M10<=60,"31-60",IF($M10<=90,"61-90","90+"))))) | O10: =IF($H10="Outstanding",$G10,0) -> 0 | P10: =$O10*IF($M10="",0,$M10) -> 0
A11: INV-5010 | B11: Foundry Dev Collective | C11: ops@foundrydev.co | D11: 45674 | E11: 30 | F11: 45704 | G11: 15700 | H11: Paid-Partial-then-Settled | I11: 45706 | J11: 15700 | K11: 32 | L11: 2 | M11: =IF($H11="Outstanding",MAX(0,Summary!$B$3-$F11),"") | N11: =IF($M11="","",IF($M11=0,"Current",IF($M11<=30,"1-30",IF($M11<=60,"31-60",IF($M11<=90,"61-90","90+"))))) | O11: =IF($H11="Outstanding",$G11,0) -> 0 | P11: =$O11*IF($M11="",0,$M11) -> 0
A12: INV-5011 | B12: Harborline Interiors | C12: kim@harborlineinteriors.com | D12: 45681 | E12: 15 | F12: 45696 | G12: 1900 | H12: Paid | I12: 45692 | J12: 1900 | K12: 11 | L12: -4 | M12: =IF($H12="Outstanding",MAX(0,Summary!$B$3-$F12),"") | N12: =IF($M12="","",IF($M12=0,"Current",IF($M12<=30,"1-30",IF($M12<=60,"31-60",IF($M12<=90,"61-90","90+"))))) | O12: =IF($H12="Outstanding",$G12,0) -> 0 | P12: =$O12*IF($M12="",0,$M12) -> 0
A13: INV-5012 | B13: Seoul Pharma Trading | C13: finance@seoulpharma.co | D13: 45673 | E13: 30 | F13: 45703 | G13: 18000 | H13: Paid | I13: 45715 | J13: 18000 | K13: 42 | L13: 12 | M13: =IF($H13="Outstanding",MAX(0,Summary!$B$3-$F13),"") | N13: =IF($M13="","",IF($M13=0,"Current",IF($M13<=30,"1-30",IF($M13<=60,"31-60",IF($M13<=90,"61-90","90+"))))) | O13: =IF($H13="Outstanding",$G13,0) -> 0 | P13: =$O13*IF($M13="",0,$M13) -> 0
... A167: INV-5166 | B167: Seoul Pharma Trading | C167: finance@seoulpharma.co | D167: 46057 | E167: 30 | F167: 46087 | G167: 7200 | H167: Paid | I167: 46125 | J167: 7200 | K167: 68 | L167: 38 | M167: =IF($H167="Outstanding",MAX(0,Summary!$B$3-$F167),"") | N167: =IF($M167="","",IF($M167=0,"Current",IF($M167<=30,"1-30",IF($M167<=60,"31-60",IF($M167<=90,"61-90","90+"))))) | O167: =IF($H167="Outstanding",$G167,0) -> 0 | P167: =$O167*IF($M167="",0,$M167) -> 0
A168: INV-5167 | B168: Northgate Property Mgmt | C168: vendors@northgatepm.com | D168: 46062 | E168: 30 | F168: 46092 | G168: 2300 | H168: Outstanding | J168: 0 | M168: =IF($H168="Outstanding",MAX(0,Summary!$B$3-$F168),"") -> 133 | N168: =IF($M168="","",IF($M168=0,"Current",IF($M168<=30,"1-30",IF($M168<=60,"31-60",IF($M168<=90,"61-90","90+"))))) -> 90+ | O168: =IF($H168="Outstanding",$G168,0) -> 2300 | P168: =$O168*IF($M168="",0,$M168) -> 305900
A169: INV-5168 | B169: TrueNorth MSP | C169: billing@truenorthmsp.com | D169: 46056 | E169: 15 | F169: 46071 | G169: 4200 | H169: Paid | I169: 46076 | J169: 4200 | K169: 20 | L169: 4 | M169: =IF($H169="Outstanding",MAX(0,Summary!$B$3-$F169),"") | N169: =IF($M169="","",IF($M169=0,"Current",IF($M169<=30,"1-30",IF($M169<=60,"31-60",IF($M169<=90,"61-90","90+"))))) | O169: =IF($H169="Outstanding",$G169,0) -> 0 | P169: =$O169*IF($M169="",0,$M169) -> 0
A170: INV-5169 | B170: Ridgeline Builders | C170: ap@ridgelinebuilders.com | D170: 46078 | E170: 30 | F170: 46108 | G170: 17300 | H170: Outstanding | J170: 0 | M170: =IF($H170="Outstanding",MAX(0,Summary!$B$3-$F170),"") -> 117 | N170: =IF($M170="","",IF($M170=0,"Current",IF($M170<=30,"1-30",IF($M170<=60,"31-60",IF($M170<=90,"61-90","90+"))))) -> 90+ | O170: =IF($H170="Outstanding",$G170,0) -> 17300 | P170: =$O170*IF($M170="",0,$M170) -> 2024100
A171: INV-5170 | B171: Bluefin Seafood Dist | C171: payables@bluefindist.com | D171: 46072 | E171: 30 | F171: 46102 | G171: 5250 | H171: Paid | I171: 46125 | J171: 5250 | K171: 53 | L171: 21 | M171: =IF($H171="Outstanding",MAX(0,Summary!$B$3-$F171),"") | N171: =IF($M171="","",IF($M171=0,"Current",IF($M171<=30,"1-30",IF($M171<=60,"31-60",IF($M171<=90,"61-90","90+"))))) | O171: =IF($H171="Outstanding",$G171,0) -> 0 | P171: =$O171*IF($M171="",0,$M171) -> 0
A172: INV-5171 | B172: Orchid Labs | C172: finance@orchidlabs.io | D172: 46072 | E172: 30 | F172: 46102 | G172: 9150 | H172: Paid | I172: 46113 | J172: 9150 | K172: 41 | L172: 11 | M172: =IF($H172="Outstanding",MAX(0,Summary!$B$3-$F172),"") | N172: =IF($M172="","",IF($M172=0,"Current",IF($M172<=30,"1-30",IF($M172<=60,"31-60",IF($M172<=90,"61-90","90+"))))) | O172: =IF($H172="Outstanding",$G172,0) -> 0 | P172: =$O172*IF($M172="",0,$M172) -> 0
A173: INV-5172 | B173: BlueRidge Hotels | C173: karen.wu@blueridgehotels.com | D173: 46076 | E173: 30 | F173: 46106 | G173: 10300 | H173: Paid | I173: 46121 | J173: 10300 | K173: 45 | L173: 15 | M173: =IF($H173="Outstanding",MAX(0,Summary!$B$3-$F173),"") | N173: =IF($M173="","",IF($M173=0,"Current",IF($M173<=30,"1-30",IF($M173<=60,"31-60",IF($M173<=90,"61-90","90+"))))) | O173: =IF($H173="Outstanding",$G173,0) -> 0 | P173: =$O173*IF($M173="",0,$M173) -> 0
A174: INV-5173 | B174: Seoul Pharma Trading | C174: finance@seoulpharma.co | D174: 46069 | E174: 30 | F174: 46099 | G174: 6000 | H174: Paid | I174: 46134 | J174: 6000 | K174: 65 | L174: 35 | M174: =IF($H174="Outstanding",MAX(0,Summary!$B$3-$F174),"") | N174: =IF($M174="","",IF($M174=0,"Current",IF($M174<=30,"1-30",IF($M174<=60,"31-60",IF($M174<=90,"61-90","90+"))))) | O174: =IF($H174="Outstanding",$G174,0) -> 0 | P174: =$O174*IF($M174="",0,$M174) -> 0
A175: INV-5174 | B175: Harborline Interiors | C175: kim@harborlineinteriors.com | D175: 46062 | E175: 15 | F175: 46077 | G175: 3000 | H175: Paid | I175: 46079 | J175: 3000 | K175: 17 | L175: 2 | M175: =IF($H175="Outstanding",MAX(0,Summary!$B$3-$F175),"") | N175: =IF($M175="","",IF($M175=0,"Current",IF($M175<=30,"1-30",IF($M175<=60,"31-60",IF($M175<=90,"61-90","90+"))))) | O175: =IF($H175="Outstanding",$G175,0) -> 0 | P175: =$O175*IF($M175="",0,$M175) -> 0
A176: INV-5175 | B176: Quarry & Co Wholesale | C176: ap@quarryco.com | D176: 46065 | E176: 30 | F176: 46095 | G176: 7300 | H176: Paid | I176: 46118 | J176: 7300 | K176: 53 | L176: 21 | M176: =IF($H176="Outstanding",MAX(0,Summary!$B$3-$F176),"") | N176: =IF($M176="","",IF($M176=0,"Current",IF($M176<=30,"1-30",IF($M176<=60,"31-60",IF($M176<=90,"61-90","90+"))))) | O176: =IF($H176="Outstanding",$G176,0) -> 0 | P176: =$O176*IF($M176="",0,$M176) -> 0
A177: INV-5176 | B177: Lakeshore Events | C177: accounts@lakeshoreevents.com | D177: 46055 | E177: 30 | F177: 46085 | G177: 6800 | H177: Paid | I177: 46118 | J177: 6800 | K177: 63 | L177: 32 | M177: =IF($H177="Outstanding",MAX(0,Summary!$B$3-$F177),"") | N177: =IF($M177="","",IF($M177=0,"Current",IF($M177<=30,"1-30",IF($M177<=60,"31-60",IF($M177<=90,"61-90","90+"))))) | O177: =IF($H177="Outstanding",$G177,0) -> 0 | P177: =$O177*IF($M177="",0,$M177) -> 0
A178: INV-5177 | B178: Cascade Logistics | C178: payables@cascadelogistics.com | D178: 46091 | E178: 30 | F178: 46121 | G178: 10300 | H178: Paid | I178: 46136 | J178: 10300 | K178: 45 | L178: 15 | M178: =IF($H178="Outstanding",MAX(0,Summary!$B$3-$F178),"") | N178: =IF($M178="","",IF($M178=0,"Current",IF($M178<=30,"1-30",IF($M178<=60,"31-60",IF($M178<=90,"61-90","90+"))))) | O178: =IF($H178="Outstanding",$G178,0) -> 0 | P178: =$O178*IF($M178="",0,$M178) -> 0
A179: INV-5178 | B179: Quarry & Co Wholesale | C179: ap@quarryco.com | D179: 46101 | E179: 30 | F179: 46131 | G179: 8150 | H179: Paid | I179: 46146 | J179: 8150 | K179: 45 | L179: 15 | M179: =IF($H179="Outstanding",MAX(0,Summary!$B$3-$F179),"") | N179: =IF($M179="","",IF($M179=0,"Current",IF($M179<=30,"1-30",IF($M179<=60,"31-60",IF($M179<=90,"61-90","90+"))))) | O179: =IF($H179="Outstanding",$G179,0) -> 0 | P179: =$O179*IF($M179="",0,$M179) -> 0
A180: INV-5179 | B180: Granite Civil Group | C180: ap@granitecivil.com | D180: 46094 | E180: 45 | F180: 46139 | G180: 22050 | H180: Outstanding | J180: 0 | M180: =IF($H180="Outstanding",MAX(0,Summary!$B$3-$F180),"") -> 86 | N180: =IF($M180="","",IF($M180=0,"Current",IF($M180<=30,"1-30",IF($M180<=60,"31-60",IF($M180<=90,"61-90","90+"))))) -> 61-90 | O180: =IF($H180="Outstanding",$G180,0) -> 22050 | P180: =$O180*IF($M180="",0,$M180) -> 1896300
A181: INV-5180 | B181: Apex Mechanical | C181: accounts@apexmech.com | D181: 46083 | E181: 30 | F181: 46113 | G181: 4850 | H181: Paid | I181: 46115 | J181: 4850 | K181: 32 | L181: 2 | M181: =IF($H181="Outstanding",MAX(0,Summary!$B$3-$F181),"") | N181: =IF($M181="","",IF($M181=0,"Current",IF($M181<=30,"1-30",IF($M181<=60,"31-60",IF($M181<=90,"61-90","90+"))))) | O181: =IF($H181="Outstanding",$G181,0) -> 0 | P181: =$O181*IF($M181="",0,$M181) -> 0
A182: INV-5181 | B182: Meridian Health Partners | C182: billing@meridianhp.com | D182: 46100 | E182: 30 | F182: 46130 | G182: 10150 | H182: Paid | I182: 46153 | J182: 10150 | K182: 53 | L182: 23 | M182: =IF($H182="Outstanding",MAX(0,Summary!$B$3-$F182),"") | N182: =IF($M182="","",IF($M182=0,"Current",IF($M182<=30,"1-30",IF($M182<=60,"31-60",IF($M182<=90,"61-90","90+"))))) | O182: =IF($H182="Outstanding",$G182,0) -> 0 | P182: =$O182*IF($M182="",0,$M182) -> 0
A183: INV-5182 | B183: Ridgeline Builders | C183: ap@ridgelinebuilders.com | D183: 46086 | E183: 30 | F183: 46116 | G183: 23250 | H183: Outstanding | J183: 0 | M183: =IF($H183="Outstanding",MAX(0,Summary!$B$3-$F183),"") -> 109 | N183: =IF($M183="","",IF($M183=0,"Current",IF($M183<=30,"1-30",IF($M183<=60,"31-60",IF($M183<=90,"61-90","90+"))))) -> 90+ | O183: =IF($H183="Outstanding",$G183,0) -> 23250 | P183: =$O183*IF($M183="",0,$M183) -> 2534250
A184: INV-5183 | B184: TrueNorth MSP | C184: billing@truenorthmsp.com | D184: 46097 | E184: 15 | F184: 46112 | G184: 3800 | H184: Paid | I184: 46115 | J184: 3800 | K184: 18 | L184: 3 | M184: =IF($H184="Outstanding",MAX(0,Summary!$B$3-$F184),"") | N184: =IF($M184="","",IF($M184=0,"Current",IF($M184<=30,"1-30",IF($M184<=60,"31-60",IF($M184<=90,"61-90","90+"))))) | O184: =IF($H184="Outstanding",$G184,0) -> 0 | P184: =$O184*IF($M184="",0,$M184) -> 0
A185: INV-5184 | B185: Harborline Interiors | C185: kim@harborlineinteriors.com | D185: 46104 | E185: 15 | F185: 46119 | G185: 1100 | H185: Paid | I185: 46119 | J185: 1100 | K185: 15 | L185: 0 | M185: =IF($H185="Outstanding",MAX(0,Summary!$B$3-$F185),"") | N185: =IF($M185="","",IF($M185=0,"Current",IF($M185<=30,"1-30",IF($M185<=60,"31-60",IF($M185<=90,"61-90","90+"))))) | O185: =IF($H185="Outstanding",$G185,0) -> 0 | P185: =$O185*IF($M185="",0,$M185) -> 0
A186: INV-5185 | B186: Seoul Pharma Trading | C186: finance@seoulpharma.co | D186: 46104 | E186: 30 | F186: 46134 | G186: 7600 | H186: Paid | I186: 46178 | J186: 7600 | K186: 74 | L186: 44 | M186: =IF($H186="Outstanding",MAX(0,Summary!$B$3-$F186),"") | N186: =IF($M186="","",IF($M186=0,"Current",IF($M186<=30,"1-30",IF($M186<=60,"31-60",IF($M186<=90,"61-90","90+"))))) | O186: =IF($H186="Outstanding",$G186,0) -> 0 | P186: =$O186*IF($M186="",0,$M186) -> 0
A187: INV-5186 | B187: Stellar Staffing Co | C187: finance@stellarstaffing.co | D187: 46097 | E187: 15 | F187: 46112 | G187: 13900 | H187: Paid | I187: 46118 | J187: 13900 | K187: 21 | L187: 5 | M187: =IF($H187="Outstanding",MAX(0,Summary!$B$3-$F187),"") | N187: =IF($M187="","",IF($M187=0,"Current",IF($M187<=30,"1-30",IF($M187<=60,"31-60",IF($M187<=90,"61-90","90+"))))) | O187: =IF($H187="Outstanding",$G187,0) -> 0 | P187: =$O187*IF($M187="",0,$M187) -> 0
A188: INV-5187 | B188: Vantage Media Group | C188: ap@vantagemedia.group | D188: 46101 | E188: 30 | F188: 46131 | G188: 5050 | H188: Outstanding | J188: 0 | M188: =IF($H188="Outstanding",MAX(0,Summary!$B$3-$F188),"") -> 94 | N188: =IF($M188="","",IF($M188=0,"Current",IF($M188<=30,"1-30",IF($M188<=60,"31-60",IF($M188<=90,"61-90","90+"))))) -> 90+ | O188: =IF($H188="Outstanding",$G188,0) -> 5050 | P188: =$O188*IF($M188="",0,$M188) -> 474700
A189: INV-5188 | B189: Bluefin Seafood Dist | C189: payables@bluefindist.com | D189: 46097 | E189: 30 | F189: 46127 | G189: 7750 | H189: Paid | I189: 46149 | J189: 7750 | K189: 52 | L189: 22 | M189: =IF($H189="Outstanding",MAX(0,Summary!$B$3-$F189),"") | N189: =IF($M189="","",IF($M189=0,"Current",IF($M189<=30,"1-30",IF($M189<=60,"31-60",IF($M189<=90,"61-90","90+"))))) | O189: =IF($H189="Outstanding",$G189,0) -> 0 | P189: =$O189*IF($M189="",0,$M189) -> 0
A190: INV-5189 | B190: Seoul Pharma Trading | C190: finance@seoulpharma.co | D190: 46104 | E190: 30 | F190: 46134 | G190: 13950 | H190: Paid | I190: 46181 | J190: 13950 | K190: 77 | L190: 47 | M190: =IF($H190="Outstanding",MAX(0,Summary!$B$3-$F190),"") | N190: =IF($M190="","",IF($M190=0,"Current",IF($M190<=30,"1-30",IF($M190<=60,"31-60",IF($M190<=90,"61-90","90+"))))) | O190: =IF($H190="Outstanding",$G190,0) -> 0 | P190: =$O190*IF($M190="",0,$M190) -> 0
A191: INV-5190 | B191: Cascade Logistics | C191: payables@cascadelogistics.com | D191: 46084 | E191: 30 | F191: 46114 | G191: 17900 | H191: Paid | I191: 46118 | J191: 17900 | K191: 34 | L191: 4 | M191: =IF($H191="Outstanding",MAX(0,Summary!$B$3-$F191),"") | N191: =IF($M191="","",IF($M191=0,"Current",IF($M191<=30,"1-30",IF($M191<=60,"31-60",IF($M191<=90,"61-90","90+"))))) | O191: =IF($H191="Outstanding",$G191,0) -> 0 | P191: =$O191*IF($M191="",0,$M191) -> 0
A192: INV-5191 | B192: Ridgeline Builders | C192: ap@ridgelinebuilders.com | D192: 46099 | E192: 30 | F192: 46129 | G192: 18200 | H192: Outstanding | J192: 0 | M192: =IF($H192="Outstanding",MAX(0,Summary!$B$3-$F192),"") -> 96 | N192: =IF($M192="","",IF($M192=0,"Current",IF($M192<=30,"1-30",IF($M192<=60,"31-60",IF($M192<=90,"61-90","90+"))))) -> 90+ | O192: =IF($H192="Outstanding",$G192,0) -> 18200 | P192: =$O192*IF($M192="",0,$M192) -> 1747200
A193: INV-5192 | B193: Foundry Dev Collective | C193: ops@foundrydev.co | D193: 46104 | E193: 30 | F193: 46134 | G193: 33100 | H193: Paid | I193: 46160 | J193: 33100 | K193: 56 | L193: 26 | M193: =IF($H193="Outstanding",MAX(0,Summary!$B$3-$F193),"") | N193: =IF($M193="","",IF($M193=0,"Current",IF($M193<=30,"1-30",IF($M193<=60,"31-60",IF($M193<=90,"61-90","90+"))))) | O193: =IF($H193="Outstanding",$G193,0) -> 0 | P193: =$O193*IF($M193="",0,$M193) -> 0
...

Sheet Summary
A1: AR Aging & Payment Behavior Analysis
A2: Demo dataset: 250 historical invoices, Jan 2025 - Jul 2026. All names and figures are fictional.
A3: Analysis date: | B3: 46225 | C3: (blue on yellow = editable input; everything else is formula-driven)
A5: Headline numbers
A6: Invoices in dump | B6: =COUNTA(Data!$A$2:$A$251) -> 250
A7: Invoices paid | B7: =SUMPRODUCT(--(LEFT(Data!$H$2:$H$251,4)="Paid")) -> 219
A8: Invoices outstanding | B8: =COUNTIF(Data!$H$2:$H$251,"Outstanding") -> 31
A9: Total billed (18 months) | B9: =SUM(Data!$G$2:$G$251) -> 2575650
A10: Average monthly billing | B10: =B9/19 -> 135560.53
A11: Open AR today | B11: =SUM(Data!$O$2:$O$251) -> 407550
A12: Value-weighted avg days to pay (paid invoices) | B12: =SUMPRODUCT((LEFT(Data!$H$2:$H$251,4)="Paid")*Data!$K$2:$K$251*Data!$G$2:$G$251)/SUMPRODUCT((LEFT(Data!$H$2:$H$251,4)="Paid")*Data!$G$2:$G$251) -> 49.609428
A13: Value-weighted avg credit terms | B13: =SUMPRODUCT(Data!$E$2:$E$251*Data!$G$2:$G$251)/SUM(Data!$G$2:$G$251) -> 30.374469
A14: Extra credit days granted beyond terms | B14: =B12-B13 -> 19.234959
A15: Cash locked by slow collection (approx.) | B15: =B10*(B14/30) -> 86916.706
A16: The sentence that matters (auto-built):
A17: ="You collect at "&TEXT(B12,"0.0")&" days against "&TEXT(B13,"0")&"-day terms. That gap parks roughly "&TEXT(B15,"$#,##0")&" of your cash with customers, permanently." -> You collect at 49.6 days against 30-day terms. That gap parks roughly $86,917 of your cash with customers, permanently.
A19: Aging of open AR
A20: Current | B20: =SUMIF(Data!$N$2:$N$251,"Current",Data!$O$2:$O$251) -> 172850 | C20: =IFERROR(B20/$B$11,0) -> 0.42411974
A21: 1-30 | B21: =SUMIF(Data!$N$2:$N$251,"1-30",Data!$O$2:$O$251) -> 109050 | C21: =IFERROR(B21/$B$11,0) -> 0.26757453
A22: 31-60 | B22: =SUMIF(Data!$N$2:$N$251,"31-60",Data!$O$2:$O$251) -> 37500 | C22: =IFERROR(B22/$B$11,0) -> 0.09201325
A23: 61-90 | B23: =SUMIF(Data!$N$2:$N$251,"61-90",Data!$O$2:$O$251) -> 22050 | C23: =IFERROR(B23/$B$11,0) -> 0.054103791
A24: 90+ | B24: =SUMIF(Data!$N$2:$N$251,"90+",Data!$O$2:$O$251) -> 66100 | C24: =IFERROR(B24/$B$11,0) -> 0.16218869

Sheet AgingByCustomer
A1: Customer | B1: Open # | C1: Current | D1: 1-30 | E1: 31-60 | F1: 61-90 | G1: 90+ | H1: Total open | I1: Value-weighted age (days)
A2: Ridgeline Builders | B2: =COUNTIFS(Data!$B$2:$B$251,$A2,Data!$H$2:$H$251,"Outstanding") -> 6 | C2: =SUMIFS(Data!$O$2:$O$251,Data!$B$2:$B$251,$A2,Data!$N$2:$N$251,"Current") -> 0 | D2: =SUMIFS(Data!$O$2:$O$251,Data!$B$2:$B$251,$A2,Data!$N$2:$N$251,"1-30") -> 37500 | E2: =SUMIFS(Data!$O$2:$O$251,Data!$B$2:$B$251,$A2,Data!$N$2:$N$251,"31-60") -> 18950 | F2: =SUMIFS(Data!$O$2:$O$251,Data!$B$2:$B$251,$A2,Data!$N$2:$N$251,"61-90") -> 0 | G2: =SUMIFS(Data!$O$2:$O$251,Data!$B$2:$B$251,$A2,Data!$N$2:$N$251,"90+") -> 58750 | H2: =SUMIFS(Data!$O$2:$O$251,Data!$B$2:$B$251,$A2) -> 115200 | I2: =IFERROR(SUMIFS(Data!$P$2:$P$251,Data!$B$2:$B$251,$A2)/H2,0) -> 61.877604
A3: Granite Civil Group | B3: =COUNTIFS(Data!$B$2:$B$251,$A3,Data!$H$2:$H$251,"Outstanding") -> 3 | C3: =SUMIFS(Data!$O$2:$O$251,Data!$B$2:$B$251,$A3,Data!$N$2:$N$251,"Current") -> 31600 | D3: =SUMIFS(Data!$O$2:$O$251,Data!$B$2:$B$251,$A3,Data!$N$2:$N$251,"1-30") -> 26250 | E3: =SUMIFS(Data!$O$2:$O$251,Data!$B$2:$B$251,$A3,Data!$N$2:$N$251,"31-60") -> 0 | F3: =SUMIFS(Data!$O$2:$O$251,Data!$B$2:$B$251,$A3,Data!$N$2:$N$251,"61-90") -> 22050 | G3: =SUMIFS(Data!$O$2:$O$251,Data!$B$2:$B$251,$A3,Data!$N$2:$N$251,"90+") -> 0 | H3: =SUMIFS(Data!$O$2:$O$251,Data!$B$2:$B$251,$A3) -> 79900 | I3: =IFERROR(SUMIFS(Data!$P$2:$P$251,Data!$B$2:$B$251,$A3)/H3,0) -> 28.00438
A4: Foundry Dev Collective | B4: =COUNTIFS(Data!$B$2:$B$251,$A4,Data!$H$2:$H$251,"Outstanding") -> 2 | C4: =SUMIFS(Data!$O$2:$O$251,Data!$B$2:$B$251,$A4,Data!$N$2:$N$251,"Current") -> 24700 | D4: =SUMIFS(Data!$O$2:$O$251,Data!$B$2:$B$251,$A4,Data!$N$2:$N$251,"1-30") -> 29400 | E4: =SUMIFS(Data!$O$2:$O$251,Data!$B$2:$B$251,$A4,Data!$N$2:$N$251,"31-60") -> 0 | F4: =SUMIFS(Data!$O$2:$O$251,Data!$B$2:$B$251,$A4,Data!$N$2:$N$251,"61-90") -> 0 | G4: =SUMIFS(Data!$O$2:$O$251,Data!$B$2:$B$251,$A4,Data!$N$2:$N$251,"90+") -> 0 | H4: =SUMIFS(Data!$O$2:$O$251,Data!$B$2:$B$251,$A4) -> 54100 | I4: =IFERROR(SUMIFS(Data!$P$2:$P$251,Data!$B$2:$B$251,$A4)/H4,0) -> 7.6081331
A5: Vantage Media Group | B5: =COUNTIFS(Data!$B$2:$B$251,$A5,Data!$H$2:$H$251,"Outstanding") -> 4 | C5: =SUMIFS(Data!$O$2:$O$251,Data!$B$2:$B$251,$A5,Data!$N$2:$N$251,"Current") -> 19000 | D5: =SUMIFS(Data!$O$2:$O$251,Data!$B$2:$B$251,$A5,Data!$N$2:$N$251,"1-30") -> 3250 | E5: =SUMIFS(Data!$O$2:$O$251,Data!$B$2:$B$251,$A5,Data!$N$2:$N$251,"31-60") -> 0 | F5: =SUMIFS(Data!$O$2:$O$251,Data!$B$2:$B$251,$A5,Data!$N$2:$N$251,"61-90") -> 0 | G5: =SUMIFS(Data!$O$2:$O$251,Data!$B$2:$B$251,$A5,Data!$N$2:$N$251,"90+") -> 5050 | H5: =SUMIFS(Data!$O$2:$O$251,Data!$B$2:$B$251,$A5) -> 27300 | I5: =IFERROR(SUMIFS(Data!$P$2:$P$251,Data!$B$2:$B$251,$A5)/H5,0) -> 19.650183
A6: Cascade Logistics | B6: =COUNTIFS(Data!$B$2:$B$251,$A6,Data!$H$2:$H$251,"Outstanding") -> 1 | C6: =SUMIFS(Data!$O$2:$O$251,Data!$B$2:$B$251,$A6,Data!$N$2:$N$251,"Current") -> 23450 | D6: =SUMIFS(Data!$O$2:$O$251,Data!$B$2:$B$251,$A6,Data!$N$2:$N$251,"1-30") -> 0 | E6: =SUMIFS(Data!$O$2:$O$251,Data!$B$2:$B$251,$A6,Data!$N$2:$N$251,"31-60") -> 0 | F6: =SUMIFS(Data!$O$2:$O$251,Data!$B$2:$B$251,$A6,Data!$N$2:$N$251,"61-90") -> 0 | G6: =SUMIFS(Data!$O$2:$O$251,Data!$B$2:$B$251,$A6,Data!$N$2:$N$251,"90+") -> 0 | H6: =SUMIFS(Data!$O$2:$O$251,Data!$B$2:$B$251,$A6) -> 23450 | I6: =IFERROR(SUMIFS(Data!$P$2:$P$251,Data!$B$2:$B$251,$A6)/H6,0) -> 0
A7: Meridian Health Partners | B7: =COUNTIFS(Data!$B$2:$B$251,$A7,Data!$H$2:$H$251,"Outstanding") -> 2 | C7: =SUMIFS(Data!$O$2:$O$251,Data!$B$2:$B$251,$A7,Data!$N$2:$N$251,"Current") -> 11950 | D7: =SUMIFS(Data!$O$2:$O$251,Data!$B$2:$B$251,$A7,Data!$N$2:$N$251,"1-30") -> 10050 | E7: =SUMIFS(Data!$O$2:$O$251,Data!$B$2:$B$251,$A7,Data!$N$2:$N$251,"31-60") -> 0 | F7: =SUMIFS(Data!$O$2:$O$251,Data!$B$2:$B$251,$A7,Data!$N$2:$N$251,"61-90") -> 0 | G7: =SUMIFS(Data!$O$2:$O$251,Data!$B$2:$B$251,$A7,Data!$N$2:$N$251,"90+") -> 0 | H7: =SUMIFS(Data!$O$2:$O$251,Data!$B$2:$B$251,$A7) -> 22000 | I7: =IFERROR(SUMIFS(Data!$P$2:$P$251,Data!$B$2:$B$251,$A7)/H7,0) -> 3.1977273
A8: Seoul Pharma Trading | B8: =COUNTIFS(Data!$B$2:$B$251,$A8,Data!$H$2:$H$251,"Outstanding") -> 1 | C8: =SUMIFS(Data!$O$2:$O$251,Data!$B$2:$B$251,$A8,Data!$N$2:$N$251,"Current") -> 0 | D8: =SUMIFS(Data!$O$2:$O$251,Data!$B$2:$B$251,$A8,Data!$N$2:$N$251,"1-30") -> 0 | E8: =SUMIFS(Data!$O$2:$O$251,Data!$B$2:$B$251,$A8,Data!$N$2:$N$251,"31-60") -> 18550 | F8: =SUMIFS(Data!$O$2:$O$251,Data!$B$2:$B$251,$A8,Data!$N$2:$N$251,"61-90") -> 0 | G8: =SUMIFS(Data!$O$2:$O$251,Data!$B$2:$B$251,$A8,Data!$N$2:$N$251,"90+") -> 0 | H8: =SUMIFS(Data!$O$2:$O$251,Data!$B$2:$B$251,$A8) -> 18550 | I8: =IFERROR(SUMIFS(Data!$P$2:$P$251,Data!$B$2:$B$251,$A8)/H8,0) -> 35
A9: Stellar Staffing Co | B9: =COUNTIFS(Data!$B$2:$B$251,$A9,Data!$H$2:$H$251,"Outstanding") -> 1 | C9: =SUMIFS(Data!$O$2:$O$251,Data!$B$2:$B$251,$A9,Data!$N$2:$N$251,"Current") -> 14400 | D9: =SUMIFS(Data!$O$2:$O$251,Data!$B$2:$B$251,$A9,Data!$N$2:$N$251,"1-30") -> 0 | E9: =SUMIFS(Data!$O$2:$O$251,Data!$B$2:$B$251,$A9,Data!$N$2:$N$251,"31-60") -> 0 | F9: =SUMIFS(Data!$O$2:$O$251,Data!$B$2:$B$251,$A9,Data!$N$2:$N$251,"61-90") -> 0 | G9: =SUMIFS(Data!$O$2:$O$251,Data!$B$2:$B$251,$A9,Data!$N$2:$N$251,"90+") -> 0 | H9: =SUMIFS(Data!$O$2:$O$251,Data!$B$2:$B$251,$A9) -> 14400 | I9: =IFERROR(SUMIFS(Data!$P$2:$P$251,Data!$B$2:$B$251,$A9)/H9,0) -> 0
A10: Quarry & Co Wholesale | B10: =COUNTIFS(Data!$B$2:$B$251,$A10,Data!$H$2:$H$251,"Outstanding") -> 2 | C10: =SUMIFS(Data!$O$2:$O$251,Data!$B$2:$B$251,$A10,Data!$N$2:$N$251,"Current") -> 14300 | D10: =SUMIFS(Data!$O$2:$O$251,Data!$B$2:$B$251,$A10,Data!$N$2:$N$251,"1-30") -> 0 | E10: =SUMIFS(Data!$O$2:$O$251,Data!$B$2:$B$251,$A10,Data!$N$2:$N$251,"31-60") -> 0 | F10: =SUMIFS(Data!$O$2:$O$251,Data!$B$2:$B$251,$A10,Data!$N$2:$N$251,"61-90") -> 0 | G10: =SUMIFS(Data!$O$2:$O$251,Data!$B$2:$B$251,$A10,Data!$N$2:$N$251,"90+") -> 0 | H10: =SUMIFS(Data!$O$2:$O$251,Data!$B$2:$B$251,$A10) -> 14300 | I10: =IFERROR(SUMIFS(Data!$P$2:$P$251,Data!$B$2:$B$251,$A10)/H10,0) -> 0
A11: Northgate Property Mgmt | B11: =COUNTIFS(Data!$B$2:$B$251,$A11,Data!$H$2:$H$251,"Outstanding") -> 4 | C11: =SUMIFS(Data!$O$2:$O$251,Data!$B$2:$B$251,$A11,Data!$N$2:$N$251,"Current") -> 7900 | D11: =SUMIFS(Data!$O$2:$O$251,Data!$B$2:$B$251,$A11,Data!$N$2:$N$251,"1-30") -> 2600 | E11: =SUMIFS(Data!$O$2:$O$251,Data!$B$2:$B$251,$A11,Data!$N$2:$N$251,"31-60") -> 0 | F11: =SUMIFS(Data!$O$2:$O$251,Data!$B$2:$B$251,$A11,Data!$N$2:$N$251,"61-90") -> 0 | G11: =SUMIFS(Data!$O$2:$O$251,Data!$B$2:$B$251,$A11,Data!$N$2:$N$251,"90+") -> 2300 | H11: =SUMIFS(Data!$O$2:$O$251,Data!$B$2:$B$251,$A11) -> 12800 | I11: =IFERROR(SUMIFS(Data!$P$2:$P$251,Data!$B$2:$B$251,$A11)/H11,0) -> 25.929688
A12: BlueRidge Hotels | B12: =COUNTIFS(Data!$B$2:$B$251,$A12,Data!$H$2:$H$251,"Outstanding") -> 1 | C12: =SUMIFS(Data!$O$2:$O$251,Data!$B$2:$B$251,$A12,Data!$N$2:$N$251,"Current") -> 9050 | D12: =SUMIFS(Data!$O$2:$O$251,Data!$B$2:$B$251,$A12,Data!$N$2:$N$251,"1-30") -> 0 | E12: =SUMIFS(Data!$O$2:$O$251,Data!$B$2:$B$251,$A12,Data!$N$2:$N$251,"31-60") -> 0 | F12: =SUMIFS(Data!$O$2:$O$251,Data!$B$2:$B$251,$A12,Data!$N$2:$N$251,"61-90") -> 0 | G12: =SUMIFS(Data!$O$2:$O$251,Data!$B$2:$B$251,$A12,Data!$N$2:$N$251,"90+") -> 0 | H12: =SUMIFS(Data!$O$2:$O$251,Data!$B$2:$B$251,$A12) -> 9050 | I12: =IFERROR(SUMIFS(Data!$P$2:$P$251,Data!$B$2:$B$251,$A12)/H12,0) -> 0
A13: Apex Mechanical | B13: =COUNTIFS(Data!$B$2:$B$251,$A13,Data!$H$2:$H$251,"Outstanding") -> 1 | C13: =SUMIFS(Data!$O$2:$O$251,Data!$B$2:$B$251,$A13,Data!$N$2:$N$251,"Current") -> 6800 | D13: =SUMIFS(Data!$O$2:$O$251,Data!$B$2:$B$251,$A13,Data!$N$2:$N$251,"1-30") -> 0 | E13: =SUMIFS(Data!$O$2:$O$251,Data!$B$2:$B$251,$A13,Data!$N$2:$N$251,"31-60") -> 0 | F13: =SUMIFS(Data!$O$2:$O$251,Data!$B$2:$B$251,$A13,Data!$N$2:$N$251,"61-90") -> 0 | G13: =SUMIFS(Data!$O$2:$O$251,Data!$B$2:$B$251,$A13,Data!$N$2:$N$251,"90+") -> 0 | H13: =SUMIFS(Data!$O$2:$O$251,Data!$B$2:$B$251,$A13) -> 6800 | I13: =IFERROR(SUMIFS(Data!$P$2:$P$251,Data!$B$2:$B$251,$A13)/H13,0) -> 0
... A19: Orchid Labs | B19: =COUNTIFS(Data!$B$2:$B$251,$A19,Data!$H$2:$H$251,"Outstanding") -> 0 | C19: =SUMIFS(Data!$O$2:$O$251,Data!$B$2:$B$251,$A19,Data!$N$2:$N$251,"Current") -> 0 | D19: =SUMIFS(Data!$O$2:$O$251,Data!$B$2:$B$251,$A19,Data!$N$2:$N$251,"1-30") -> 0 | E19: =SUMIFS(Data!$O$2:$O$251,Data!$B$2:$B$251,$A19,Data!$N$2:$N$251,"31-60") -> 0 | F19: =SUMIFS(Data!$O$2:$O$251,Data!$B$2:$B$251,$A19,Data!$N$2:$N$251,"61-90") -> 0 | G19: =SUMIFS(Data!$O$2:$O$251,Data!$B$2:$B$251,$A19,Data!$N$2:$N$251,"90+") -> 0 | H19: =SUMIFS(Data!$O$2:$O$251,Data!$B$2:$B$251,$A19) -> 0 | I19: =IFERROR(SUMIFS(Data!$P$2:$P$251,Data!$B$2:$B$251,$A19)/H19,0) -> 0
A20: TOTAL | B20: =SUM(B2:B19) -> 31 | C20: =SUM(C2:C19) -> 172850 | D20: =SUM(D2:D19) -> 109050 | E20: =SUM(E2:E19) -> 37500 | F20: =SUM(F2:F19) -> 22050 | G20: =SUM(G2:G19) -> 66100 | H20: =SUM(H2:H19) -> 407550

Sheet CustomerBehavior
A1: Customer | B1: Invoices (18 mo) | C1: Lifetime billed | D1: Avg days to pay | E1: Terms (days) | F1: Avg days late | G1: Late trend (2nd half vs 1st, days) | H1: Behavior read
A2: Ridgeline Builders | B2: =COUNTIF(Data!$B$2:$B$251,$A2) -> 15 | C2: =SUMIF(Data!$B$2:$B$251,$A2,Data!$G$2:$G$251) -> 225200 | D2: =IFERROR(AVERAGEIFS(Data!$K$2:$K$251,Data!$B$2:$B$251,$A2,Data!$H$2:$H$251,"Paid*"),"n/a") -> 69.222222 | E2: 30 | F2: =IFERROR(AVERAGEIFS(Data!$L$2:$L$251,Data!$B$2:$B$251,$A2,Data!$H$2:$H$251,"Paid*"),"n/a") -> 38.555556 | G2: 4.1 | H2: Problem payer, account-level intervention required
A3: Granite Civil Group | B3: =COUNTIF(Data!$B$2:$B$251,$A3) -> 12 | C3: =SUMIF(Data!$B$2:$B$251,$A3,Data!$G$2:$G$251) -> 299500 | D3: =IFERROR(AVERAGEIFS(Data!$K$2:$K$251,Data!$B$2:$B$251,$A3,Data!$H$2:$H$251,"Paid*"),"n/a") -> 70.444444 | E3: 45 | F3: =IFERROR(AVERAGEIFS(Data!$L$2:$L$251,Data!$B$2:$B$251,$A3,Data!$H$2:$H$251,"Paid*"),"n/a") -> 25.444444 | G3: -1.9 | H3: Chronically slow, needs firm consistent follow-up
A4: Foundry Dev Collective | B4: =COUNTIF(Data!$B$2:$B$251,$A4) -> 13 | C4: =SUMIF(Data!$B$2:$B$251,$A4,Data!$G$2:$G$251) -> 291900 | D4: =IFERROR(AVERAGEIFS(Data!$K$2:$K$251,Data!$B$2:$B$251,$A4,Data!$H$2:$H$251,"Paid*"),"n/a") -> 40.636364 | E4: 30 | F4: =IFERROR(AVERAGEIFS(Data!$L$2:$L$251,Data!$B$2:$B$251,$A4,Data!$H$2:$H$251,"Paid*"),"n/a") -> 9.7272727 | G4: 4.3 | H4: Mildly slow, standard cadence works
A5: Vantage Media Group | B5: =COUNTIF(Data!$B$2:$B$251,$A5) -> 14 | C5: =SUMIF(Data!$B$2:$B$251,$A5,Data!$G$2:$G$251) -> 108600 | D5: =IFERROR(AVERAGEIFS(Data!$K$2:$K$251,Data!$B$2:$B$251,$A5,Data!$H$2:$H$251,"Paid*"),"n/a") -> 89.7 | E5: 30 | F5: =IFERROR(AVERAGEIFS(Data!$L$2:$L$251,Data!$B$2:$B$251,$A5,Data!$H$2:$H$251,"Paid*"),"n/a") -> 58.9 | G5: 4.6 | H5: Problem payer, account-level intervention required
A6: Cascade Logistics | B6: =COUNTIF(Data!$B$2:$B$251,$A6) -> 13 | C6: =SUMIF(Data!$B$2:$B$251,$A6,Data!$G$2:$G$251) -> 308850 | D6: =IFERROR(AVERAGEIFS(Data!$K$2:$K$251,Data!$B$2:$B$251,$A6,Data!$H$2:$H$251,"Paid*"),"n/a") -> 40 | E6: 30 | F6: =IFERROR(AVERAGEIFS(Data!$L$2:$L$251,Data!$B$2:$B$251,$A6,Data!$H$2:$H$251,"Paid*"),"n/a") -> 9.4166667 | G6: -3.8 | H6: Mildly slow, standard cadence works
A7: Meridian Health Partners | B7: =COUNTIF(Data!$B$2:$B$251,$A7) -> 16 | C7: =SUMIF(Data!$B$2:$B$251,$A7,Data!$G$2:$G$251) -> 147100 | D7: =IFERROR(AVERAGEIFS(Data!$K$2:$K$251,Data!$B$2:$B$251,$A7,Data!$H$2:$H$251,"Paid*"),"n/a") -> 44.928571 | E7: 30 | F7: =IFERROR(AVERAGEIFS(Data!$L$2:$L$251,Data!$B$2:$B$251,$A7,Data!$H$2:$H$251,"Paid*"),"n/a") -> 14.714286 | G7: 11.1 | H7: Mildly slow, standard cadence works | DETERIORATING, investigate now
A8: Seoul Pharma Trading | B8: =COUNTIF(Data!$B$2:$B$251,$A8) -> 17 | C8: =SUMIF(Data!$B$2:$B$251,$A8,Data!$G$2:$G$251) -> 201900 | D8: =IFERROR(AVERAGEIFS(Data!$K$2:$K$251,Data!$B$2:$B$251,$A8,Data!$H$2:$H$251,"Paid*"),"n/a") -> 65.6875 | E8: 30 | F8: =IFERROR(AVERAGEIFS(Data!$L$2:$L$251,Data!$B$2:$B$251,$A8,Data!$H$2:$H$251,"Paid*"),"n/a") -> 35.4375 | G8: 8.1 | H8: Problem payer, account-level intervention required | DETERIORATING, investigate now
A9: Stellar Staffing Co | B9: =COUNTIF(Data!$B$2:$B$251,$A9) -> 8 | C9: =SUMIF(Data!$B$2:$B$251,$A9,Data!$G$2:$G$251) -> 104300 | D9: =IFERROR(AVERAGEIFS(Data!$K$2:$K$251,Data!$B$2:$B$251,$A9,Data!$H$2:$H$251,"Paid*"),"n/a") -> 18.714286 | E9: 15 | F9: =IFERROR(AVERAGEIFS(Data!$L$2:$L$251,Data!$B$2:$B$251,$A9,Data!$H$2:$H$251,"Paid*"),"n/a") -> 3.2857143 | G9: 0.5 | H9: Reliable payer, protect the relationship
A10: Quarry & Co Wholesale | B10: =COUNTIF(Data!$B$2:$B$251,$A10) -> 20 | C10: =SUMIF(Data!$B$2:$B$251,$A10,Data!$G$2:$G$251) -> 138950 | D10: =IFERROR(AVERAGEIFS(Data!$K$2:$K$251,Data!$B$2:$B$251,$A10,Data!$H$2:$H$251,"Paid*"),"n/a") -> 55.777778 | E10: 30 | F10: =IFERROR(AVERAGEIFS(Data!$L$2:$L$251,Data!$B$2:$B$251,$A10,Data!$H$2:$H$251,"Paid*"),"n/a") -> 25.277778 | G10: -6.8 | H10: Chronically slow, needs firm consistent follow-up
A11: Northgate Property Mgmt | B11: =COUNTIF(Data!$B$2:$B$251,$A11) -> 20 | C11: =SUMIF(Data!$B$2:$B$251,$A11,Data!$G$2:$G$251) -> 82650 | D11: =IFERROR(AVERAGEIFS(Data!$K$2:$K$251,Data!$B$2:$B$251,$A11,Data!$H$2:$H$251,"Paid*"),"n/a") -> 74 | E11: 30 | F11: =IFERROR(AVERAGEIFS(Data!$L$2:$L$251,Data!$B$2:$B$251,$A11,Data!$H$2:$H$251,"Paid*"),"n/a") -> 43.625 | G11: -6.2 | H11: Problem payer, account-level intervention required
A12: BlueRidge Hotels | B12: =COUNTIF(Data!$B$2:$B$251,$A12) -> 20 | C12: =SUMIF(Data!$B$2:$B$251,$A12,Data!$G$2:$G$251) -> 240850 | D12: =IFERROR(AVERAGEIFS(Data!$K$2:$K$251,Data!$B$2:$B$251,$A12,Data!$H$2:$H$251,"Paid*"),"n/a") -> 45.315789 | E12: 30 | F12: =IFERROR(AVERAGEIFS(Data!$L$2:$L$251,Data!$B$2:$B$251,$A12,Data!$H$2:$H$251,"Paid*"),"n/a") -> 14.684211 | G12: 3 | H12: Mildly slow, standard cadence works
A13: Apex Mechanical | B13: =COUNTIF(Data!$B$2:$B$251,$A13) -> 17 | C13: =SUMIF(Data!$B$2:$B$251,$A13,Data!$G$2:$G$251) -> 85300 | D13: =IFERROR(AVERAGEIFS(Data!$K$2:$K$251,Data!$B$2:$B$251,$A13,Data!$H$2:$H$251,"Paid*"),"n/a") -> 35 | E13: 30 | F13: =IFERROR(AVERAGEIFS(Data!$L$2:$L$251,Data!$B$2:$B$251,$A13,Data!$H$2:$H$251,"Paid*"),"n/a") -> 4.5625 | G13: -2.9 | H13: Reliable payer, protect the relationship
... A19: Orchid Labs | B19: =COUNTIF(Data!$B$2:$B$251,$A19) -> 7 | C19: =SUMIF(Data!$B$2:$B$251,$A19,Data!$G$2:$G$251) -> 50550 | D19: =IFERROR(AVERAGEIFS(Data!$K$2:$K$251,Data!$B$2:$B$251,$A19,Data!$H$2:$H$251,"Paid*"),"n/a") -> 40.857143 | E19: 30 | F19: =IFERROR(AVERAGEIFS(Data!$L$2:$L$251,Data!$B$2:$B$251,$A19,Data!$H$2:$H$251,"Paid*"),"n/a") -> 10.285714 | G19: -0.7 | H19: Mildly slow, standard cadence works
A21: Note: 'Late trend' is computed in the source dump (average lateness of the customer's second half of paid invoices minus the first half). Positive = getting slower. Hardcoded blue by design; recompute from Data when refreshed.

Sheet PriorityTop10
A1: Where the energy goes: top 10 by cash impact, not by metric
A2: Impact = open value x value-weighted age. A $100 invoice 100 days old never outranks a $30K invoice 45 days old.
A4: Rank | B4: Customer | C4: Open value | D4: Value-weighted age | E4: Impact score | F4: Avg late (hist.) | G4: Recommended first move
A5: 1 | B5: Ridgeline Builders | C5: =AgingByCustomer!H2 -> 115200 | D5: =AgingByCustomer!I2 -> 61.877604 | E5: =C5*MAX(1,D5) -> 7128300 | F5: =IFERROR(AVERAGEIFS(Data!$L$2:$L$251,Data!$B$2:$B$251,$B5,Data!$H$2:$H$251,"Paid*"),"n/a") -> 38.555556 | G5: Account-level call today; consolidate all open invoices into one written plan (history: honors plans).
A6: 2 | B6: Granite Civil Group | C6: =AgingByCustomer!H3 -> 79900 | D6: =AgingByCustomer!I3 -> 28.00438 | E6: =C6*MAX(1,D6) -> 2237550 | F6: =IFERROR(AVERAGEIFS(Data!$L$2:$L$251,Data!$B$2:$B$251,$B6,Data!$H$2:$H$251,"Paid*"),"n/a") -> 25.444444 | G6: Confirm retainage/release milestones in writing; escalate the 90+ item with a dated final notice.
A7: 3 | B7: Seoul Pharma Trading | C7: =AgingByCustomer!H8 -> 18550 | D7: =AgingByCustomer!I8 -> 35 | E7: =C7*MAX(1,D7) -> 649250 | F7: =IFERROR(AVERAGEIFS(Data!$L$2:$L$251,Data!$B$2:$B$251,$B7,Data!$H$2:$H$251,"Paid*"),"n/a") -> 35.4375 | G7: Broken-promise pattern: quote their last commitment back, require a dated schedule.
A8: 4 | B8: Vantage Media Group | C8: =AgingByCustomer!H5 -> 27300 | D8: =AgingByCustomer!I5 -> 19.650183 | E8: =C8*MAX(1,D8) -> 536450 | F8: =IFERROR(AVERAGEIFS(Data!$L$2:$L$251,Data!$B$2:$B$251,$B8,Data!$H$2:$H$251,"Paid*"),"n/a") -> 58.9 | G8: Chronic 55+ days: move to prepay or tightened terms at renewal; firm ladder on all open items now.
A9: 5 | B9: Foundry Dev Collective | C9: =AgingByCustomer!H4 -> 54100 | D9: =AgingByCustomer!I4 -> 7.6081331 | E9: =C9*MAX(1,D9) -> 411600 | F9: =IFERROR(AVERAGEIFS(Data!$L$2:$L$251,Data!$B$2:$B$251,$B9,Data!$H$2:$H$251,"Paid*"),"n/a") -> 9.7272727 | G9: Verify acceptance sign-off on milestones; isolate any disputed line and collect the clean balance.
A10: 6 | B10: Northgate Property Mgmt | C10: =AgingByCustomer!H11 -> 12800 | D10: =AgingByCustomer!I11 -> 25.929688 | E10: =C10*MAX(1,D10) -> 331900 | F10: =IFERROR(AVERAGEIFS(Data!$L$2:$L$251,Data!$B$2:$B$251,$B10,Data!$H$2:$H$251,"Paid*"),"n/a") -> 43.625 | G10: Fixed-cycle payer: align invoice submission to their run cutoff; chase the cycle, not the person.
A11: 7 | B11: Meridian Health Partners | C11: =AgingByCustomer!H7 -> 22000 | D11: =AgingByCustomer!I7 -> 3.1977273 | E11: =C11*MAX(1,D11) -> 70350 | F11: =IFERROR(AVERAGEIFS(Data!$L$2:$L$251,Data!$B$2:$B$251,$B11,Data!$H$2:$H$251,"Paid*"),"n/a") -> 14.714286 | G11: Trend +11 days and worsening: relationship call this week to find the cause before it compounds.
A12: 8 | B12: Cascade Logistics | C12: =AgingByCustomer!H6 -> 23450 | D12: =AgingByCustomer!I6 -> 0 | E12: =C12*MAX(1,D12) -> 23450 | F12: =IFERROR(AVERAGEIFS(Data!$L$2:$L$251,Data!$B$2:$B$251,$B12,Data!$H$2:$H$251,"Paid*"),"n/a") -> 9.4166667 | G12: Single large invoice: direct AP status call; likely approval-cycle issue, not refusal.
A13: 9 | B13: Stellar Staffing Co | C13: =AgingByCustomer!H9 -> 14400 | D13: =AgingByCustomer!I9 -> 0 | E13: =C13*MAX(1,D13) -> 14400 | F13: =IFERROR(AVERAGEIFS(Data!$L$2:$L$251,Data!$B$2:$B$251,$B13,Data!$H$2:$H$251,"Paid*"),"n/a") -> 3.2857143 | G13: Reliable: gentle nudge only; protect the relationship.
A14: 10 | B14: Quarry & Co Wholesale | C14: =AgingByCustomer!H10 -> 14300 | D14: =AgingByCustomer!I10 -> 0 | E14: =C14*MAX(1,D14) -> 14300 | F14: =IFERROR(AVERAGEIFS(Data!$L$2:$L$251,Data!$B$2:$B$251,$B14,Data!$H$2:$H$251,"Paid*"),"n/a") -> 25.277778 | G14: Standard ladder; consider order-hold trade if a new PO arrives before payment.
